Workbook

Sheet Summary
A1: IP Distribution Decision Verticals: Cost Variance Model
A2: ="Paperback $"&TEXT(Assumptions!$B$6,"0.00")&", "&Assumptions!$B$7&" pages | Ebook $"&TEXT(Assumptions!$B$8,"0.00")&" | "&Assumptions!$B$10&" print + "&Assumptions!$B$11&" ebook units/mo" -> Paperback $16.99, 200 pages | Ebook $4.99 | 50 print + 50 ebook units/mo
A3: Edit inputs on the Assumptions sheet. Everything on this page recalculates.
A4: Prices, fees and rates as of October 11, 2026. Refreshed quarterly; next refresh January 11, 2027.
A5: Platform | B5: Print net / unit | C5: Print variance vs baseline | D5: Ebook net / unit | E5: Ebook variance vs baseline | F5: Year-1 fixed costs | G5: Year-1 net after fixed costs | H5: Year-1 variance vs baseline | I5: Rank
A6: Amazon KDP | B6: ='Monthly Scenario'!D5 -> 6.794 | C6: =INDEX('Print Unit Econ'!$I$5:$I$11,MATCH('Monthly Scenario'!B5,'Print Unit Econ'!$A$5:$A$11,0)) -> 0 | D6: ='Monthly Scenario'!E5 -> 3.283 | E6: =INDEX('Ebook Unit Econ'!$I$5:$I$11,MATCH('Monthly Scenario'!C5,'Ebook Unit Econ'!$A$5:$A$11,0)) -> 0 | F6: ='Fixed Costs'!J5 -> 0 | G6: ='Monthly Scenario'!M5 -> 6046.2 | H6: ='Monthly Scenario'!N5 -> 0 | I6: ='Monthly Scenario'!O5 -> 1
A7: IngramSpark | B7: ='Monthly Scenario'!D6 -> 3.3269375 | C7: =INDEX('Print Unit Econ'!$I$5:$I$11,MATCH('Monthly Scenario'!B6,'Print Unit Econ'!$A$5:$A$11,0)) -> -3.4670625 | D7: ='Monthly Scenario'!E6 -> 2.96905 | E7: =INDEX('Ebook Unit Econ'!$I$5:$I$11,MATCH('Monthly Scenario'!C6,'Ebook Unit Econ'!$A$5:$A$11,0)) -> -0.31395 | F7: ='Fixed Costs'!J6 -> 125 | G7: ='Monthly Scenario'!M6 -> 3652.5925 | H7: ='Monthly Scenario'!N6 -> -2393.6075 | I7: ='Monthly Scenario'!O6 -> 4
A8: B&N Press | B8: ='Monthly Scenario'!D7 -> 5.8445 | C8: =INDEX('Print Unit Econ'!$I$5:$I$11,MATCH('Monthly Scenario'!B7,'Print Unit Econ'!$A$5:$A$11,0)) -> -0.9495 | D8: ='Monthly Scenario'!E7 -> 3.493 | E8: =INDEX('Ebook Unit Econ'!$I$5:$I$11,MATCH('Monthly Scenario'!C7,'Ebook Unit Econ'!$A$5:$A$11,0)) -> 0.21 | F8: ='Fixed Costs'!J7 -> 20 | G8: ='Monthly Scenario'!M7 -> 5477.5 | H8: ='Monthly Scenario'!N7 -> -568.7 | I8: ='Monthly Scenario'!O7 -> 2
A9: Lulu | B9: ='Monthly Scenario'!D8 -> 2.796 | C9: =INDEX('Print Unit Econ'!$I$5:$I$11,MATCH('Monthly Scenario'!B8,'Print Unit Econ'!$A$5:$A$11,0)) -> -3.998 | D9: ='Monthly Scenario'!E8 -> 1.996 | E9: =INDEX('Ebook Unit Econ'!$I$5:$I$11,MATCH('Monthly Scenario'!C8,'Ebook Unit Econ'!$A$5:$A$11,0)) -> -1.287 | F9: ='Fixed Costs'!J8 -> 125 | G9: ='Monthly Scenario'!M8 -> 2863.2 | H9: ='Monthly Scenario'!N8 -> -3183 | I9: ='Monthly Scenario'!O8 -> 5
A10: PublishDrive | B10: ='Monthly Scenario'!D9 -> 3.6455 | C10: =INDEX('Print Unit Econ'!$I$5:$I$11,MATCH('Monthly Scenario'!B9,'Print Unit Econ'!$A$5:$A$11,0)) -> -3.1485 | D10: ='Monthly Scenario'!E9 -> 3.493 | E10: =INDEX('Ebook Unit Econ'!$I$5:$I$11,MATCH('Monthly Scenario'!C9,'Ebook Unit Econ'!$A$5:$A$11,0)) -> 0.21 | F10: ='Fixed Costs'!J9 -> 12 | G10: ='Monthly Scenario'!M9 -> 3990.22 | H10: ='Monthly Scenario'!N9 -> -2055.98 | I10: ='Monthly Scenario'!O9 -> 3
A11: Draft2Digital | B11: n/a | C11: n/a | D11: ='Monthly Scenario'!E10 -> 3.1437 | E11: =INDEX('Ebook Unit Econ'!$I$5:$I$11,MATCH('Monthly Scenario'!C10,'Ebook Unit Econ'!$A$5:$A$11,0)) -> -0.1393 | F11: ='Fixed Costs'!J10 -> 292.88 | G11: ='Monthly Scenario'!M10 -> 1866.22 | H11: ='Monthly Scenario'!N10 -> -4179.98 | I11: ='Monthly Scenario'!O10 -> 6
A13: Key takeaways (at default assumptions)
A14: 1. KDP pays the most per print copy on Amazon because Amazon takes 40% versus the 55% bookstore discount used for IngramSpark and PublishDrive.
A15: 2. The channel share (retailer discount) is the largest variance driver for print, larger than print cost or platform fees. See the driver columns on Print Unit Econ.
A16: 3. For ebooks, direct uploads (KDP, Apple, B&N) beat aggregators; aggregators trade a 10 to 15% cut for one-upload reach.
A17: 4. PublishDrive only beats IngramSpark or Draft2Digital above the break-even volume on the Volume Sensitivity sheet; below it, the subscription costs more than it saves.
A18: 5. Lulu retail distribution is the weakest per-unit option; Lulu only wins on sales through its own bookstore or your site.
A19: 6. Yellow cells on Assumptions are estimates. Replace them with each platform's calculator output before making a decision.

Sheet Assumptions
A1: IP Distribution Decision Verticals: Assumptions
A2: Legend: blue text = input you can edit; yellow fill = key assumption to replace with your own calculator results; black = formula.
A4: Assumption | B4: Value | C4: Unit | D4: Notes / Source
A5: Book inputs
A6: Paperback list price | B6: 16.99 | C6: USD | D6: Example value. Replace with your planned price.
A7: Paperback page count | B7: 200 | C7: pages | D7: Example: 6x9 black-and-white interior.
A8: Ebook list price | B8: 4.99 | C8: USD | D8: Example value.
A9: Ebook file size | B9: 2 | C9: MB | D9: Text-only ebooks are usually under 2 MB. Drives KDP delivery fee.
A10: Print units sold per month (per platform) | B10: 50 | C10: units | D10: Scenario lever used on the Monthly Scenario sheet.
A11: Ebook units sold per month (per platform) | B11: 50 | C11: units | D11: Scenario lever used on the Monthly Scenario sheet.
A12: Baseline for variance
A13: Print baseline platform | B13: Amazon KDP | C13: text | D13: Every print variance is measured against this row. Pick from the dropdown.
A14: Ebook baseline platform | B14: Amazon KDP | C14: text | D14: Every ebook variance is measured against this row. Pick from the dropdown.
A15: Combined baseline platform | B15: Amazon KDP | C15: text | D15: Baseline for the Monthly Scenario sheet.
A16: Amazon KDP
A17: KDP print royalty rate (Amazon.com sales) | B17: 0.6 | C17: % | D17: 60% of list minus printing cost. Source: Vappingo, KDP Print Royalties.
A18: KDP Expanded Distribution royalty rate | B18: 0.4 | C18: % | D18: 40% of list minus printing cost. Source: BestWriting, KDP Royalties Explained.
A19: KDP flat print cost (24 to 108 pages) | B19: 2.3 | C19: USD | D19: Source: Profitable.app KDP calculator (2026). Some sources list $2.15.
A20: KDP fixed print cost (110+ pages) | B20: 1 | C20: USD | D20: Source: Profitable.app (2026). Some sources list $0.85; verify in KDP's calculator.
A21: KDP per-page print cost (B&W) | B21: 0.012 | C21: USD/page | D21: Source: Profitable.app; BestWriting.
A22: KDP ebook royalty, $2.99 to $9.99 | B22: 0.7 | C22: % | D22: Source: Daniel Tortora royalty guide (2026).
A23: KDP ebook royalty outside that band | B23: 0.35 | C23: % | D23: No delivery fee on the 35% tier.
A24: KDP delivery fee (70% tier) | B24: 0.15 | C24: USD/MB | D24: US store. Source: Reedsy; Profitable.app.
A25: IngramSpark
A26: IngramSpark wholesale discount | B26: 0.55 | C26: % | D26: 55% is standard for bookstore stocking; 35 to 40% is common for online-only. Source: Tortora.
A27: IngramSpark market access fee | B27: 0.01875 | C27: % of list | D27: Effective Feb 1, 2026. Source: IngramSpark Help Center.
A28: Ingram print cost per unit (estimate) | B28: 4 | C28: USD | D28: ESTIMATE. Replace with IngramSpark print cost calculator result. Also used for PublishDrive (prints via Ingram).
A29: IngramSpark digital distribution fee | B29: 0.15 | C29: % of net sales | D29: Sec. 8.1.3 of the IngramSpark Agreement you pasted.
A30: Barnes & Noble Press
A31: B&N Press print royalty rate | B31: 0.55 | C31: % | D31: 55% of list minus per-book printing cost. Source: B&N Press Help Center.
A32: B&N Press print cost per unit (estimate) | B32: 3.5 | C32: USD | D32: ESTIMATE. B&N does not publish a formula; check its calculator during setup.
A33: B&N Press ebook royalty | B33: 0.7 | C33: % | D33: Flat 70% for ebooks priced $0.99 and up. Source: B&N Press Help Center.
A34: Lulu
A35: Lulu print cost per unit (estimate) | B35: 5 | C35: USD | D35: ESTIMATE. Replace with Lulu pricing calculator result.
A36: Lulu retail distribution fee | B36: 0.5 | C36: % of list | D36: 50% of gross revenue on retail channels; none on Lulu Bookstore. Source: Chapter, Lulu Pricing (Sep 2026).
A37: Lulu commission | B37: 0.2 | C37: % of gross profit | D37: Lulu keeps 20% of what remains after fees and print. Source: Chapter, Lulu Pricing.
A38: Ebook stores and aggregators
A39: Apple / Kobo / Google payout rate to publisher | B39: 0.7 | C39: % | D39: Source: ScribeCount platform comparison.
A40: Draft2Digital share of store payout | B40: 0.1 | C40: % | D40: D2D keeps about 10%, you net about 90% of the store payout. Source: Books.by; Publishing.co.uk.
A41: Fixed and recurring costs
...

Sheet Print Unit Econ
A1: Print Book: Per-Unit Royalty and Variance vs Baseline
A2: ="Baseline: "&Assumptions!$B$13&" | List price: "&TEXT(Assumptions!$B$6,"$0.00")&" | Pages: "&Assumptions!$B$7 -> Baseline: Amazon KDP | List price: $16.99 | Pages: 200
A4: Platform | B4: Where it sells | C4: List price | D4: Retailer / channel share | E4: Print cost | F4: Platform fees | G4: Net royalty per unit | H4: Net % of list | I4: Variance vs baseline ($) | J4: Variance vs baseline (%) | K4: Driver: channel share | L4: Driver: print cost | M4: Driver: platform fees | N4: Rank
A5: Amazon KDP | B5: Amazon.com only | C5: =Assumptions!$B$6 -> 16.99 | D5: =Assumptions!$B$6*(1-Assumptions!$B$17) -> 6.796 | E5: =IF(Assumptions!$B$7<=108,Assumptions!$B$19,Assumptions!$B$20+Assumptions!$B$7*Assumptions!$B$21) -> 3.4 | F5: =0 -> 0 | G5: =C5-D5-E5-F5 -> 6.794 | H5: =IFERROR(G5/C5,0) -> 0.39988228 | I5: =G5-INDEX($G$5:$G$11,MATCH(Assumptions!$B$13,$A$5:$A$11,0)) -> 0 | J5: =IFERROR(I5/ABS(INDEX($G$5:$G$11,MATCH(Assumptions!$B$13,$A$5:$A$11,0))),0) -> 0 | K5: =INDEX($D$5:$D$11,MATCH(Assumptions!$B$13,$A$5:$A$11,0))-D5 -> 0 | L5: =INDEX($E$5:$E$11,MATCH(Assumptions!$B$13,$A$5:$A$11,0))-E5 -> 0 | M5: =INDEX($F$5:$F$11,MATCH(Assumptions!$B$13,$A$5:$A$11,0))-F5 -> 0 | N5: =RANK(G5,$G$5:$G$11) -> 2
A6: KDP Expanded Distribution | B6: Other retailers via KDP | C6: =Assumptions!$B$6 -> 16.99 | D6: =Assumptions!$B$6*(1-Assumptions!$B$18) -> 10.194 | E6: =IF(Assumptions!$B$7<=108,Assumptions!$B$19,Assumptions!$B$20+Assumptions!$B$7*Assumptions!$B$21) -> 3.4 | F6: =0 -> 0 | G6: =C6-D6-E6-F6 -> 3.396 | H6: =IFERROR(G6/C6,0) -> 0.19988228 | I6: =G6-INDEX($G$5:$G$11,MATCH(Assumptions!$B$13,$A$5:$A$11,0)) -> -3.398 | J6: =IFERROR(I6/ABS(INDEX($G$5:$G$11,MATCH(Assumptions!$B$13,$A$5:$A$11,0))),0) -> -0.50014719 | K6: =INDEX($D$5:$D$11,MATCH(Assumptions!$B$13,$A$5:$A$11,0))-D6 -> -3.398 | L6: =INDEX($E$5:$E$11,MATCH(Assumptions!$B$13,$A$5:$A$11,0))-E6 -> 0 | M6: =INDEX($F$5:$F$11,MATCH(Assumptions!$B$13,$A$5:$A$11,0))-F6 -> 0 | N6: =RANK(G6,$G$5:$G$11) -> 5
A7: IngramSpark | B7: Bookstores, libraries, online retail | C7: =Assumptions!$B$6 -> 16.99 | D7: =Assumptions!$B$6*Assumptions!$B$26 -> 9.3445 | E7: =Assumptions!$B$28 -> 4 | F7: =Assumptions!$B$6*Assumptions!$B$27 -> 0.3185625 | G7: =C7-D7-E7-F7 -> 3.3269375 | H7: =IFERROR(G7/C7,0) -> 0.19581739 | I7: =G7-INDEX($G$5:$G$11,MATCH(Assumptions!$B$13,$A$5:$A$11,0)) -> -3.4670625 | J7: =IFERROR(I7/ABS(INDEX($G$5:$G$11,MATCH(Assumptions!$B$13,$A$5:$A$11,0))),0) -> -0.51031241 | K7: =INDEX($D$5:$D$11,MATCH(Assumptions!$B$13,$A$5:$A$11,0))-D7 -> -2.5485 | L7: =INDEX($E$5:$E$11,MATCH(Assumptions!$B$13,$A$5:$A$11,0))-E7 -> -0.6 | M7: =INDEX($F$5:$F$11,MATCH(Assumptions!$B$13,$A$5:$A$11,0))-F7 -> -0.3185625 | N7: =RANK(G7,$G$5:$G$11) -> 6
A8: B&N Press | B8: BN.com (U.S. only) | C8: =Assumptions!$B$6 -> 16.99 | D8: =Assumptions!$B$6*(1-Assumptions!$B$31) -> 7.6455 | E8: =Assumptions!$B$32 -> 3.5 | F8: =0 -> 0 | G8: =C8-D8-E8-F8 -> 5.8445 | H8: =IFERROR(G8/C8,0) -> 0.34399647 | I8: =G8-INDEX($G$5:$G$11,MATCH(Assumptions!$B$13,$A$5:$A$11,0)) -> -0.9495 | J8: =IFERROR(I8/ABS(INDEX($G$5:$G$11,MATCH(Assumptions!$B$13,$A$5:$A$11,0))),0) -> -0.13975567 | K8: =INDEX($D$5:$D$11,MATCH(Assumptions!$B$13,$A$5:$A$11,0))-D8 -> -0.8495 | L8: =INDEX($E$5:$E$11,MATCH(Assumptions!$B$13,$A$5:$A$11,0))-E8 -> -0.1 | M8: =INDEX($F$5:$F$11,MATCH(Assumptions!$B$13,$A$5:$A$11,0))-F8 -> 0 | N8: =RANK(G8,$G$5:$G$11) -> 3
A9: Lulu Bookstore | B9: Lulu.com store only | C9: =Assumptions!$B$6 -> 16.99 | D9: =0 -> 0 | E9: =Assumptions!$B$35 -> 5 | F9: =(C9-D9-E9)*Assumptions!$B$37 -> 2.398 | G9: =C9-D9-E9-F9 -> 9.592 | H9: =IFERROR(G9/C9,0) -> 0.56456739 | I9: =G9-INDEX($G$5:$G$11,MATCH(Assumptions!$B$13,$A$5:$A$11,0)) -> 2.798 | J9: =IFERROR(I9/ABS(INDEX($G$5:$G$11,MATCH(Assumptions!$B$13,$A$5:$A$11,0))),0) -> 0.41183397 | K9: =INDEX($D$5:$D$11,MATCH(Assumptions!$B$13,$A$5:$A$11,0))-D9 -> 6.796 | L9: =INDEX($E$5:$E$11,MATCH(Assumptions!$B$13,$A$5:$A$11,0))-E9 -> -1.6 | M9: =INDEX($F$5:$F$11,MATCH(Assumptions!$B$13,$A$5:$A$11,0))-F9 -> -2.398 | N9: =RANK(G9,$G$5:$G$11) -> 1
A10: Lulu (Retail) | B10: Amazon, B&N, others via Lulu | C10: =Assumptions!$B$6 -> 16.99 | D10: =Assumptions!$B$6*Assumptions!$B$36 -> 8.495 | E10: =Assumptions!$B$35 -> 5 | F10: =(C10-D10-E10)*Assumptions!$B$37 -> 0.699 | G10: =C10-D10-E10-F10 -> 2.796 | H10: =IFERROR(G10/C10,0) -> 0.16456739 | I10: =G10-INDEX($G$5:$G$11,MATCH(Assumptions!$B$13,$A$5:$A$11,0)) -> -3.998 | J10: =IFERROR(I10/ABS(INDEX($G$5:$G$11,MATCH(Assumptions!$B$13,$A$5:$A$11,0))),0) -> -0.58846041 | K10: =INDEX($D$5:$D$11,MATCH(Assumptions!$B$13,$A$5:$A$11,0))-D10 -> -1.699 | L10: =INDEX($E$5:$E$11,MATCH(Assumptions!$B$13,$A$5:$A$11,0))-E10 -> -1.6 | M10: =INDEX($F$5:$F$11,MATCH(Assumptions!$B$13,$A$5:$A$11,0))-F10 -> -0.699 | N10: =RANK(G10,$G$5:$G$11) -> 7
A11: PublishDrive | B11: Bookstores and retail via Ingram | C11: =Assumptions!$B$6 -> 16.99 | D11: =Assumptions!$B$6*Assumptions!$B$26 -> 9.3445 | E11: =Assumptions!$B$28 -> 4 | F11: =0 -> 0 | G11: =C11-D11-E11-F11 -> 3.6455 | H11: =IFERROR(G11/C11,0) -> 0.21456739 | I11: =G11-INDEX($G$5:$G$11,MATCH(Assumptions!$B$13,$A$5:$A$11,0)) -> -3.1485 | J11: =IFERROR(I11/ABS(INDEX($G$5:$G$11,MATCH(Assumptions!$B$13,$A$5:$A$11,0))),0) -> -0.46342361 | K11: =INDEX($D$5:$D$11,MATCH(Assumptions!$B$13,$A$5:$A$11,0))-D11 -> -2.5485 | L11: =INDEX($E$5:$E$11,MATCH(Assumptions!$B$13,$A$5:$A$11,0))-E11 -> -0.6 | M11: =INDEX($F$5:$F$11,MATCH(Assumptions!$B$13,$A$5:$A$11,0))-F11 -> 0 | N11: =RANK(G11,$G$5:$G$11) -> 4
A13: How to read this sheet:
A14: Net royalty per unit = List price - Retailer/channel share - Print cost - Platform fees.
A15: Variance vs baseline = this platform's net minus the baseline's net. The three driver columns split that variance by cause and add up to it exactly.
A16: Positive driver = this platform costs you less than the baseline on that line. Negative = it costs you more.
A17: PublishDrive's monthly subscription is a fixed cost, so it appears on the Monthly Scenario sheet rather than here.
A18: Print costs for IngramSpark, PublishDrive, B&N Press and Lulu are estimates on the Assumptions sheet. Replace them with each platform's calculator output.

Sheet Ebook Unit Econ
A1: Ebook: Per-Unit Royalty and Variance vs Baseline
A2: ="Baseline: "&Assumptions!$B$14&" | Ebook price: "&TEXT(Assumptions!$B$8,"$0.00")&" | File size: "&Assumptions!$B$9&" MB" -> Baseline: Amazon KDP | Ebook price: $4.99 | File size: 2 MB
A4: Platform | B4: Sold through | C4: List price | D4: Store cut | E4: Delivery fee | F4: Aggregator / platform fee | G4: Net royalty per unit | H4: Net % of list | I4: Variance vs baseline ($) | J4: Variance vs baseline (%) | K4: Driver: store cut | L4: Driver: delivery fee | M4: Driver: aggregator fee | N4: Rank
A5: Amazon KDP | B5: Amazon Kindle | C5: =Assumptions!$B$8 -> 4.99 | D5: =(C5-E5)*(1-IF(AND(Assumptions!$B$8>=2.99,Assumptions!$B$8<=9.99),Assumptions!$B$22,Assumptions!$B$23)) -> 1.407 | E5: =IF(AND(Assumptions!$B$8>=2.99,Assumptions!$B$8<=9.99),Assumptions!$B$9*Assumptions!$B$24,0) -> 0.3 | F5: =0 -> 0 | G5: =C5-D5-E5-F5 -> 3.283 | H5: =IFERROR(G5/C5,0) -> 0.65791583 | I5: =G5-INDEX($G$5:$G$11,MATCH(Assumptions!$B$14,$A$5:$A$11,0)) -> 0 | J5: =IFERROR(I5/ABS(INDEX($G$5:$G$11,MATCH(Assumptions!$B$14,$A$5:$A$11,0))),0) -> 0 | K5: =INDEX($D$5:$D$11,MATCH(Assumptions!$B$14,$A$5:$A$11,0))-D5 -> 0 | L5: =INDEX($E$5:$E$11,MATCH(Assumptions!$B$14,$A$5:$A$11,0))-E5 -> 0 | M5: =INDEX($F$5:$F$11,MATCH(Assumptions!$B$14,$A$5:$A$11,0))-F5 -> 0 | N5: =RANK(G5,$G$5:$G$11) -> 4
A6: Apple Books (direct) | B6: Apple Books | C6: =Assumptions!$B$8 -> 4.99 | D6: =C6*(1-Assumptions!$B$39) -> 1.497 | E6: =0 -> 0 | F6: =0 -> 0 | G6: =C6-D6-E6-F6 -> 3.493 | H6: =IFERROR(G6/C6,0) -> 0.7 | I6: =G6-INDEX($G$5:$G$11,MATCH(Assumptions!$B$14,$A$5:$A$11,0)) -> 0.21 | J6: =IFERROR(I6/ABS(INDEX($G$5:$G$11,MATCH(Assumptions!$B$14,$A$5:$A$11,0))),0) -> 0.063965885 | K6: =INDEX($D$5:$D$11,MATCH(Assumptions!$B$14,$A$5:$A$11,0))-D6 -> -0.09 | L6: =INDEX($E$5:$E$11,MATCH(Assumptions!$B$14,$A$5:$A$11,0))-E6 -> 0.3 | M6: =INDEX($F$5:$F$11,MATCH(Assumptions!$B$14,$A$5:$A$11,0))-F6 -> 0 | N6: =RANK(G6,$G$5:$G$11) -> 1
A7: B&N Press | B7: BN.com / Nook | C7: =Assumptions!$B$8 -> 4.99 | D7: =C7*(1-Assumptions!$B$33) -> 1.497 | E7: =0 -> 0 | F7: =0 -> 0 | G7: =C7-D7-E7-F7 -> 3.493 | H7: =IFERROR(G7/C7,0) -> 0.7 | I7: =G7-INDEX($G$5:$G$11,MATCH(Assumptions!$B$14,$A$5:$A$11,0)) -> 0.21 | J7: =IFERROR(I7/ABS(INDEX($G$5:$G$11,MATCH(Assumptions!$B$14,$A$5:$A$11,0))),0) -> 0.063965885 | K7: =INDEX($D$5:$D$11,MATCH(Assumptions!$B$14,$A$5:$A$11,0))-D7 -> -0.09 | L7: =INDEX($E$5:$E$11,MATCH(Assumptions!$B$14,$A$5:$A$11,0))-E7 -> 0.3 | M7: =INDEX($F$5:$F$11,MATCH(Assumptions!$B$14,$A$5:$A$11,0))-F7 -> 0 | N7: =RANK(G7,$G$5:$G$11) -> 1
A8: Draft2Digital (via Apple) | B8: Apple, Kobo, Google, libraries | C8: =Assumptions!$B$8 -> 4.99 | D8: =C8*(1-Assumptions!$B$39) -> 1.497 | E8: =0 -> 0 | F8: =(C8-D8)*Assumptions!$B$40 -> 0.3493 | G8: =C8-D8-E8-F8 -> 3.1437 | H8: =IFERROR(G8/C8,0) -> 0.63 | I8: =G8-INDEX($G$5:$G$11,MATCH(Assumptions!$B$14,$A$5:$A$11,0)) -> -0.1393 | J8: =IFERROR(I8/ABS(INDEX($G$5:$G$11,MATCH(Assumptions!$B$14,$A$5:$A$11,0))),0) -> -0.042430704 | K8: =INDEX($D$5:$D$11,MATCH(Assumptions!$B$14,$A$5:$A$11,0))-D8 -> -0.09 | L8: =INDEX($E$5:$E$11,MATCH(Assumptions!$B$14,$A$5:$A$11,0))-E8 -> 0.3 | M8: =INDEX($F$5:$F$11,MATCH(Assumptions!$B$14,$A$5:$A$11,0))-F8 -> -0.3493 | N8: =RANK(G8,$G$5:$G$11) -> 5
A9: IngramSpark (via Apple) | B9: Ingram ebook network | C9: =Assumptions!$B$8 -> 4.99 | D9: =C9*(1-Assumptions!$B$39) -> 1.497 | E9: =0 -> 0 | F9: =(C9-D9)*Assumptions!$B$29 -> 0.52395 | G9: =C9-D9-E9-F9 -> 2.96905 | H9: =IFERROR(G9/C9,0) -> 0.595 | I9: =G9-INDEX($G$5:$G$11,MATCH(Assumptions!$B$14,$A$5:$A$11,0)) -> -0.31395 | J9: =IFERROR(I9/ABS(INDEX($G$5:$G$11,MATCH(Assumptions!$B$14,$A$5:$A$11,0))),0) -> -0.095628998 | K9: =INDEX($D$5:$D$11,MATCH(Assumptions!$B$14,$A$5:$A$11,0))-D9 -> -0.09 | L9: =INDEX($E$5:$E$11,MATCH(Assumptions!$B$14,$A$5:$A$11,0))-E9 -> 0.3 | M9: =INDEX($F$5:$F$11,MATCH(Assumptions!$B$14,$A$5:$A$11,0))-F9 -> -0.52395 | N9: =RANK(G9,$G$5:$G$11) -> 6
A10: PublishDrive (via Apple) | B10: 400+ stores | C10: =Assumptions!$B$8 -> 4.99 | D10: =C10*(1-Assumptions!$B$39) -> 1.497 | E10: =0 -> 0 | F10: =0 -> 0 | G10: =C10-D10-E10-F10 -> 3.493 | H10: =IFERROR(G10/C10,0) -> 0.7 | I10: =G10-INDEX($G$5:$G$11,MATCH(Assumptions!$B$14,$A$5:$A$11,0)) -> 0.21 | J10: =IFERROR(I10/ABS(INDEX($G$5:$G$11,MATCH(Assumptions!$B$14,$A$5:$A$11,0))),0) -> 0.063965885 | K10: =INDEX($D$5:$D$11,MATCH(Assumptions!$B$14,$A$5:$A$11,0))-D10 -> -0.09 | L10: =INDEX($E$5:$E$11,MATCH(Assumptions!$B$14,$A$5:$A$11,0))-E10 -> 0.3 | M10: =INDEX($F$5:$F$11,MATCH(Assumptions!$B$14,$A$5:$A$11,0))-F10 -> 0 | N10: =RANK(G10,$G$5:$G$11) -> 1
A11: Lulu (Retail) | B11: Retailers via Lulu | C11: =Assumptions!$B$8 -> 4.99 | D11: =C11*Assumptions!$B$36 -> 2.495 | E11: =0 -> 0 | F11: =(C11-D11)*Assumptions!$B$37 -> 0.499 | G11: =C11-D11-E11-F11 -> 1.996 | H11: =IFERROR(G11/C11,0) -> 0.4 | I11: =G11-INDEX($G$5:$G$11,MATCH(Assumptions!$B$14,$A$5:$A$11,0)) -> -1.287 | J11: =IFERROR(I11/ABS(INDEX($G$5:$G$11,MATCH(Assumptions!$B$14,$A$5:$A$11,0))),0) -> -0.39201949 | K11: =INDEX($D$5:$D$11,MATCH(Assumptions!$B$14,$A$5:$A$11,0))-D11 -> -1.088 | L11: =INDEX($E$5:$E$11,MATCH(Assumptions!$B$14,$A$5:$A$11,0))-E11 -> 0.3 | M11: =INDEX($F$5:$F$11,MATCH(Assumptions!$B$14,$A$5:$A$11,0))-F11 -> -0.499 | N11: =RANK(G11,$G$5:$G$11) -> 7
A13: Notes:
A14: KDP pays 70% only between $2.99 and $9.99 and charges a per-MB delivery fee on that tier; outside the band it pays 35% with no delivery fee. The formula switches automatically.
A15: Aggregator rows assume the sale happens on Apple Books (70% store payout). Kobo and Google pay similar rates.
A16: Lulu ebook economics are an estimate based on its published retail distribution fee and commission.
A17: PublishDrive keeps 0% of royalties but charges a monthly subscription, which is applied on the Monthly Scenario sheet.

Sheet Fixed Costs
A1: Fixed and Recurring Costs per Title (Year 1)
A2: Blue cells are inputs. ISBN, account, proof, and subscription values link to the Assumptions sheet.
A4: Platform | B4: Title setup fee | C4: Revision fees | D4: ISBN cost | E4: Account fee | F4: Proof copy | G4: One-time total | H4: Monthly subscription | I4: Annual subscription | J4: Year-1 fixed total | K4: Notes
A5: Amazon KDP | B5: 0 | C5: 0 | D5: =0 -> 0 | E5: =0 -> 0 | F5: =0 -> 0 | G5: =SUM(B5:F5) -> 0 | H5: =0 -> 0 | I5: =H5*12 -> 0 | J5: =G5+I5 -> 0 | K5: Free setup, free revisions, free ISBN for print. Ebooks do not need an ISBN.
A6: IngramSpark | B6: 0 | C6: 0 | D6: =Assumptions!$B$42 -> 125 | E6: =0 -> 0 | F6: =0 -> 0 | G6: =SUM(B6:F6) -> 125 | H6: =0 -> 0 | I6: =H6*12 -> 0 | J6: =G6+I6 -> 125 | K6: Setup free; revisions free since Feb 2026. U.S. publishers supply their own ISBN.
A7: Draft2Digital | B7: 0 | C7: 0 | D7: =0 -> 0 | E7: =Assumptions!$B$43 -> 20 | F7: =0 -> 0 | G7: =SUM(B7:F7) -> 20 | H7: =0 -> 0 | I7: =H7*12 -> 0 | J7: =G7+I7 -> 20 | K7: Free ISBN (D2D listed as publisher). $20 account fee for new accounts since April 2026.
A8: B&N Press | B8: 0 | C8: 0 | D8: =Assumptions!$B$42 -> 125 | E8: =0 -> 0 | F8: =0 -> 0 | G8: =SUM(B8:F8) -> 125 | H8: =0 -> 0 | I8: =H8*12 -> 0 | J8: =G8+I8 -> 125 | K8: Free ISBN covers print only; an ebook needs your own ISBN.
A9: Lulu | B9: 0 | C9: 0 | D9: =0 -> 0 | E9: =0 -> 0 | F9: =Assumptions!$B$44 -> 12 | G9: =SUM(B9:F9) -> 12 | H9: =0 -> 0 | I9: =H9*12 -> 0 | J9: =G9+I9 -> 12 | K9: Free to publish. Proof copy required before print distribution.
A10: PublishDrive | B10: 0 | C10: 0 | D10: =Assumptions!$B$42 -> 125 | E10: =0 -> 0 | F10: =0 -> 0 | G10: =SUM(B10:F10) -> 125 | H10: =Assumptions!$B$45 -> 13.99 | I10: =H10*12 -> 167.88 | J10: =G10+I10 -> 292.88 | K10: 0% commission; paid plans from $13.99/mo. Free plan covers 1 title (set subscription to 0 to model it).

Sheet Monthly Scenario
A1: Monthly and Year-1 Earnings at Assumed Volume
A2: ="Volume: "&Assumptions!$B$10&" print + "&Assumptions!$B$11&" ebook units per month per platform | Baseline: "&Assumptions!$B$15 -> Volume: 50 print + 50 ebook units per month per platform | Baseline: Amazon KDP
A4: Platform | B4: Print row used | C4: Ebook row used | D4: Print net / unit | E4: Ebook net / unit | F4: Print units / mo | G4: Ebook units / mo | H4: Monthly royalties | I4: Monthly subscription | J4: Monthly net | K4: Year-1 net (12 mo) | L4: Year-1 one-time costs | M4: Year-1 net after fixed costs | N4: Variance vs baseline (Year 1) | O4: Rank
A5: Amazon KDP | B5: Amazon KDP | C5: Amazon KDP | D5: =INDEX('Print Unit Econ'!$G$5:$G$11,MATCH(B5,'Print Unit Econ'!$A$5:$A$11,0)) -> 6.794 | E5: =INDEX('Ebook Unit Econ'!$G$5:$G$11,MATCH(C5,'Ebook Unit Econ'!$A$5:$A$11,0)) -> 3.283 | F5: =Assumptions!$B$10 -> 50 | G5: =Assumptions!$B$11 -> 50 | H5: =D5*F5+E5*G5 -> 503.85 | I5: =INDEX('Fixed Costs'!$H$5:$H$10,MATCH(A5,'Fixed Costs'!$A$5:$A$10,0)) -> 0 | J5: =H5-I5 -> 503.85 | K5: =J5*12 -> 6046.2 | L5: =INDEX('Fixed Costs'!$G$5:$G$10,MATCH(A5,'Fixed Costs'!$A$5:$A$10,0)) -> 0 | M5: =K5-L5 -> 6046.2 | N5: =M5-INDEX($M$5:$M$10,MATCH(Assumptions!$B$15,$A$5:$A$10,0)) -> 0 | O5: =RANK(M5,$M$5:$M$10) -> 1
A6: IngramSpark | B6: IngramSpark | C6: IngramSpark (via Apple) | D6: =INDEX('Print Unit Econ'!$G$5:$G$11,MATCH(B6,'Print Unit Econ'!$A$5:$A$11,0)) -> 3.3269375 | E6: =INDEX('Ebook Unit Econ'!$G$5:$G$11,MATCH(C6,'Ebook Unit Econ'!$A$5:$A$11,0)) -> 2.96905 | F6: =Assumptions!$B$10 -> 50 | G6: =Assumptions!$B$11 -> 50 | H6: =D6*F6+E6*G6 -> 314.79937 | I6: =INDEX('Fixed Costs'!$H$5:$H$10,MATCH(A6,'Fixed Costs'!$A$5:$A$10,0)) -> 0 | J6: =H6-I6 -> 314.79937 | K6: =J6*12 -> 3777.5925 | L6: =INDEX('Fixed Costs'!$G$5:$G$10,MATCH(A6,'Fixed Costs'!$A$5:$A$10,0)) -> 125 | M6: =K6-L6 -> 3652.5925 | N6: =M6-INDEX($M$5:$M$10,MATCH(Assumptions!$B$15,$A$5:$A$10,0)) -> -2393.6075 | O6: =RANK(M6,$M$5:$M$10) -> 4
A7: B&N Press | B7: B&N Press | C7: B&N Press | D7: =INDEX('Print Unit Econ'!$G$5:$G$11,MATCH(B7,'Print Unit Econ'!$A$5:$A$11,0)) -> 5.8445 | E7: =INDEX('Ebook Unit Econ'!$G$5:$G$11,MATCH(C7,'Ebook Unit Econ'!$A$5:$A$11,0)) -> 3.493 | F7: =Assumptions!$B$10 -> 50 | G7: =Assumptions!$B$11 -> 50 | H7: =D7*F7+E7*G7 -> 466.875 | I7: =INDEX('Fixed Costs'!$H$5:$H$10,MATCH(A7,'Fixed Costs'!$A$5:$A$10,0)) -> 0 | J7: =H7-I7 -> 466.875 | K7: =J7*12 -> 5602.5 | L7: =INDEX('Fixed Costs'!$G$5:$G$10,MATCH(A7,'Fixed Costs'!$A$5:$A$10,0)) -> 125 | M7: =K7-L7 -> 5477.5 | N7: =M7-INDEX($M$5:$M$10,MATCH(Assumptions!$B$15,$A$5:$A$10,0)) -> -568.7 | O7: =RANK(M7,$M$5:$M$10) -> 2
A8: Lulu | B8: Lulu (Retail) | C8: Lulu (Retail) | D8: =INDEX('Print Unit Econ'!$G$5:$G$11,MATCH(B8,'Print Unit Econ'!$A$5:$A$11,0)) -> 2.796 | E8: =INDEX('Ebook Unit Econ'!$G$5:$G$11,MATCH(C8,'Ebook Unit Econ'!$A$5:$A$11,0)) -> 1.996 | F8: =Assumptions!$B$10 -> 50 | G8: =Assumptions!$B$11 -> 50 | H8: =D8*F8+E8*G8 -> 239.6 | I8: =INDEX('Fixed Costs'!$H$5:$H$10,MATCH(A8,'Fixed Costs'!$A$5:$A$10,0)) -> 0 | J8: =H8-I8 -> 239.6 | K8: =J8*12 -> 2875.2 | L8: =INDEX('Fixed Costs'!$G$5:$G$10,MATCH(A8,'Fixed Costs'!$A$5:$A$10,0)) -> 12 | M8: =K8-L8 -> 2863.2 | N8: =M8-INDEX($M$5:$M$10,MATCH(Assumptions!$B$15,$A$5:$A$10,0)) -> -3183 | O8: =RANK(M8,$M$5:$M$10) -> 5
A9: PublishDrive | B9: PublishDrive | C9: PublishDrive (via Apple) | D9: =INDEX('Print Unit Econ'!$G$5:$G$11,MATCH(B9,'Print Unit Econ'!$A$5:$A$11,0)) -> 3.6455 | E9: =INDEX('Ebook Unit Econ'!$G$5:$G$11,MATCH(C9,'Ebook Unit Econ'!$A$5:$A$11,0)) -> 3.493 | F9: =Assumptions!$B$10 -> 50 | G9: =Assumptions!$B$11 -> 50 | H9: =D9*F9+E9*G9 -> 356.925 | I9: =INDEX('Fixed Costs'!$H$5:$H$10,MATCH(A9,'Fixed Costs'!$A$5:$A$10,0)) -> 13.99 | J9: =H9-I9 -> 342.935 | K9: =J9*12 -> 4115.22 | L9: =INDEX('Fixed Costs'!$G$5:$G$10,MATCH(A9,'Fixed Costs'!$A$5:$A$10,0)) -> 125 | M9: =K9-L9 -> 3990.22 | N9: =M9-INDEX($M$5:$M$10,MATCH(Assumptions!$B$15,$A$5:$A$10,0)) -> -2055.98 | O9: =RANK(M9,$M$5:$M$10) -> 3
A10: Draft2Digital | B10: (not modeled) | C10: Draft2Digital (via Apple) | D10: 0 | E10: =INDEX('Ebook Unit Econ'!$G$5:$G$11,MATCH(C10,'Ebook Unit Econ'!$A$5:$A$11,0)) -> 3.1437 | F10: 0 | G10: =Assumptions!$B$11 -> 50 | H10: =D10*F10+E10*G10 -> 157.185 | I10: =INDEX('Fixed Costs'!$H$5:$H$10,MATCH(A10,'Fixed Costs'!$A$5:$A$10,0)) -> 0 | J10: =H10-I10 -> 157.185 | K10: =J10*12 -> 1886.22 | L10: =INDEX('Fixed Costs'!$G$5:$G$10,MATCH(A10,'Fixed Costs'!$A$5:$A$10,0)) -> 20 | M10: =K10-L10 -> 1866.22 | N10: =M10-INDEX($M$5:$M$10,MATCH(Assumptions!$B$15,$A$5:$A$10,0)) -> -4179.98 | O10: =RANK(M10,$M$5:$M$10) -> 6
A12: Notes:
A13: Each row assumes the same unit volume on every platform so the per-sale economics can be compared directly. In practice, reach differs: KDP covers Amazon only, while IngramSpark and PublishDrive reach bookstores and libraries.
A14: Draft2Digital print (D2D Print) is not modeled because current per-unit print terms were not available; the row shows ebook earnings only.
A15: You can change which unit-economics row each platform uses in columns B and C (the names must match exactly).

Sheet Volume Sensitivity
A1: Monthly Net by Volume (equal print and ebook units)
A2: Blue volume levels in row 4 are editable. Monthly net = units x (print net + ebook net) - monthly subscription.
A4: Platform | B4: 10 units/mo | C4: 25 units/mo | D4: 50 units/mo | E4: 100 units/mo | F4: 250 units/mo | G4: 500 units/mo
A5: Units per format / month | B5: 10 | C5: 25 | D5: 50 | E5: 100 | F5: 250 | G5: 500
A6: Amazon KDP | B6: =B$5*('Monthly Scenario'!$D$5+'Monthly Scenario'!$E$5)-'Monthly Scenario'!$I$5 -> 100.77 | C6: =C$5*('Monthly Scenario'!$D$5+'Monthly Scenario'!$E$5)-'Monthly Scenario'!$I$5 -> 251.925 | D6: =D$5*('Monthly Scenario'!$D$5+'Monthly Scenario'!$E$5)-'Monthly Scenario'!$I$5 -> 503.85 | E6: =E$5*('Monthly Scenario'!$D$5+'Monthly Scenario'!$E$5)-'Monthly Scenario'!$I$5 -> 1007.7 | F6: =F$5*('Monthly Scenario'!$D$5+'Monthly Scenario'!$E$5)-'Monthly Scenario'!$I$5 -> 2519.25 | G6: =G$5*('Monthly Scenario'!$D$5+'Monthly Scenario'!$E$5)-'Monthly Scenario'!$I$5 -> 5038.5
A7: IngramSpark | B7: =B$5*('Monthly Scenario'!$D$6+'Monthly Scenario'!$E$6)-'Monthly Scenario'!$I$6 -> 62.959875 | C7: =C$5*('Monthly Scenario'!$D$6+'Monthly Scenario'!$E$6)-'Monthly Scenario'!$I$6 -> 157.39969 | D7: =D$5*('Monthly Scenario'!$D$6+'Monthly Scenario'!$E$6)-'Monthly Scenario'!$I$6 -> 314.79937 | E7: =E$5*('Monthly Scenario'!$D$6+'Monthly Scenario'!$E$6)-'Monthly Scenario'!$I$6 -> 629.59875 | F7: =F$5*('Monthly Scenario'!$D$6+'Monthly Scenario'!$E$6)-'Monthly Scenario'!$I$6 -> 1573.9969 | G7: =G$5*('Monthly Scenario'!$D$6+'Monthly Scenario'!$E$6)-'Monthly Scenario'!$I$6 -> 3147.9938
A8: B&N Press | B8: =B$5*('Monthly Scenario'!$D$7+'Monthly Scenario'!$E$7)-'Monthly Scenario'!$I$7 -> 93.375 | C8: =C$5*('Monthly Scenario'!$D$7+'Monthly Scenario'!$E$7)-'Monthly Scenario'!$I$7 -> 233.4375 | D8: =D$5*('Monthly Scenario'!$D$7+'Monthly Scenario'!$E$7)-'Monthly Scenario'!$I$7 -> 466.875 | E8: =E$5*('Monthly Scenario'!$D$7+'Monthly Scenario'!$E$7)-'Monthly Scenario'!$I$7 -> 933.75 | F8: =F$5*('Monthly Scenario'!$D$7+'Monthly Scenario'!$E$7)-'Monthly Scenario'!$I$7 -> 2334.375 | G8: =G$5*('Monthly Scenario'!$D$7+'Monthly Scenario'!$E$7)-'Monthly Scenario'!$I$7 -> 4668.75
A9: Lulu | B9: =B$5*('Monthly Scenario'!$D$8+'Monthly Scenario'!$E$8)-'Monthly Scenario'!$I$8 -> 47.92 | C9: =C$5*('Monthly Scenario'!$D$8+'Monthly Scenario'!$E$8)-'Monthly Scenario'!$I$8 -> 119.8 | D9: =D$5*('Monthly Scenario'!$D$8+'Monthly Scenario'!$E$8)-'Monthly Scenario'!$I$8 -> 239.6 | E9: =E$5*('Monthly Scenario'!$D$8+'Monthly Scenario'!$E$8)-'Monthly Scenario'!$I$8 -> 479.2 | F9: =F$5*('Monthly Scenario'!$D$8+'Monthly Scenario'!$E$8)-'Monthly Scenario'!$I$8 -> 1198 | G9: =G$5*('Monthly Scenario'!$D$8+'Monthly Scenario'!$E$8)-'Monthly Scenario'!$I$8 -> 2396
A10: PublishDrive | B10: =B$5*('Monthly Scenario'!$D$9+'Monthly Scenario'!$E$9)-'Monthly Scenario'!$I$9 -> 57.395 | C10: =C$5*('Monthly Scenario'!$D$9+'Monthly Scenario'!$E$9)-'Monthly Scenario'!$I$9 -> 164.4725 | D10: =D$5*('Monthly Scenario'!$D$9+'Monthly Scenario'!$E$9)-'Monthly Scenario'!$I$9 -> 342.935 | E10: =E$5*('Monthly Scenario'!$D$9+'Monthly Scenario'!$E$9)-'Monthly Scenario'!$I$9 -> 699.86 | F10: =F$5*('Monthly Scenario'!$D$9+'Monthly Scenario'!$E$9)-'Monthly Scenario'!$I$9 -> 1770.635 | G10: =G$5*('Monthly Scenario'!$D$9+'Monthly Scenario'!$E$9)-'Monthly Scenario'!$I$9 -> 3555.26
A11: Draft2Digital | B11: =B$5*('Monthly Scenario'!$D$10+'Monthly Scenario'!$E$10)-'Monthly Scenario'!$I$10 -> 31.437 | C11: =C$5*('Monthly Scenario'!$D$10+'Monthly Scenario'!$E$10)-'Monthly Scenario'!$I$10 -> 78.5925 | D11: =D$5*('Monthly Scenario'!$D$10+'Monthly Scenario'!$E$10)-'Monthly Scenario'!$I$10 -> 157.185 | E11: =E$5*('Monthly Scenario'!$D$10+'Monthly Scenario'!$E$10)-'Monthly Scenario'!$I$10 -> 314.37 | F11: =F$5*('Monthly Scenario'!$D$10+'Monthly Scenario'!$E$10)-'Monthly Scenario'!$I$10 -> 785.925 | G11: =G$5*('Monthly Scenario'!$D$10+'Monthly Scenario'!$E$10)-'Monthly Scenario'!$I$10 -> 1571.85
A13: Break-even analysis
A14: PublishDrive vs IngramSpark: units/mo (each format) where PublishDrive pulls ahead | E14: =IFERROR('Monthly Scenario'!I9/(('Monthly Scenario'!D9+'Monthly Scenario'!E9)-('Monthly Scenario'!D6+'Monthly Scenario'!E6)),"n/a") -> 16.605095
A15: PublishDrive vs Draft2Digital (ebook only): ebook units/mo where PublishDrive pulls ahead | E15: =IFERROR('Monthly Scenario'!I9/('Monthly Scenario'!E9-'Monthly Scenario'!E10),"n/a") -> 40.051532

Sheet Sources
A1: Sources
A3: Topic | B3: Source | C3: URL
A4: IngramSpark 2026 fees | B4: IngramSpark Help Center: Changes in Print Cost, Market Access Fee and More | C4: https://help.ingramspark.com/hc/en-us/articles/41657495062029-Changes-in-Print-Cost-Market-Access-Fee-and-More
A5: IngramSpark digital fee, payment terms | B5: IngramSpark Agreement (pasted by user), Sec. 8 and 9 | C5: https://www.ingramspark.com/
A6: IngramSpark fees, ISBN prices | B6: ScribeCount: How to Publish on IngramSpark | C6: https://scribecount.com/author-resource/publishing-a-book/How-to-Publish-on-IngramSpark
A7: Royalty formulas across platforms | B7: Daniel Tortora: Self-Publishing Royalties 2026 | C7: https://danieljtortora.com/blog/self-publishing-royalties
A8: KDP print costs and delivery fee | B8: Profitable.app: KDP Royalty Calculator | C8: https://profitable.app/tools/kdp-royalty-calculator
A9: KDP print royalties | B9: Vappingo: KDP Print Royalties | C9: https://www.vappingo.com/word-blog/kdp-print-royalties/
A10: KDP Expanded Distribution | B10: BestWriting: KDP Royalties Explained | C10: https://bestwriting.com/kdp-royalties
A11: B&N Press royalties and payouts | B11: B&N Press Help Center: Getting Paid for Sales | C11: https://help-press.barnesandnoble.com/hc/en-us/articles/5359658688923-Getting-Paid-for-Sales
A12: Lulu fee structure | B12: Chapter: Lulu Pricing | C12: https://blog.chapter.pub/lulu-pricing/
A13: PublishDrive plans | B13: PublishDrive Help: Distribution Pricing Plans | C13: https://help.publishdrive.com/how-much-publishdrives-distribution-pricing-plans
A14: PublishDrive vs IngramSpark | B14: PublishDrive comparison (July 2026) | C14: https://publishdrive.com/publishdrive-vs-ingramspark-2026-pricing-royalties-distribution-and-features-compared.html
... A16: Ebook store payout rates | B16: ScribeCount: Platform Comparison | C16: https://scribecount.com/tools/platform-comparison
A18: Fees change often. Figures are as of October 11, 2026 and are refreshed quarterly. Not legal or financial advice.
